Workbook

Sheet Cover
A1: IFB INDUSTRIES LIMITED (NSE: IFBIND)
A2: Full-Fledge Formula-Driven Financial Model | FY2022A – FY2029E
B4: Company | C4: IFB Industries Limited
B5: Ticker | C5: NSE: IFBIND | BSE: 505726
B6: Sector | C6: Consumer Durables / Engineering Components
B7: Headquarters | C7: Kolkata, West Bengal, India
B8: CMP (Jun 2026) | C8: ₹1,097 per share
B9: Market Cap | C9: ~₹4,455 Crore
B10: Shares Outstanding | C10: 4.07 Crore (40.7 million)
B11: Face Value | C11: ₹10
B12: Fiscal Year End | C12: 31 March
B13: Currency / Unit | C13: Indian Rupees (₹) in Crores
B14: Model Date | C14: June 2026
B15: Data Sources | C15: BSE Filings, Annual Reports, Screener.in
B17: MODEL ARCHITECTURE
B18: Assumptions | C18: SINGLE SOURCE OF TRUTH — all hardcoded inputs live here; everything else is formulas
B19: P&L | C19: Income statement pulling from Assumptions via cross-sheet formulas
B20: BalanceSheet | C20: Balance sheet projections linked to P&L & Assumptions
B21: CashFlow | C21: Operating / Investing / Financing — linked to P&L & BS
B22: DCF | C22: FCFF-based intrinsic value with sensitivity table
B23: Comps | C23: Peer multiples comparison + implied valuations
B24: Ratios | C24: 25+ KPIs computed from P&L / BS — all formulas
B25: Segments | C25: Home Appliances vs Engineering split with product breakdown
B27: COLOR CODE: Blue text = hardcoded inputs | Black text = formulas | Green text = cross-sheet links | Yellow bg = key assumption cells
B28: DISCLAIMER: For educational/research purposes only. Not investment advice. Always verify data before use.

Sheet Assumptions
A1: IFB INDUSTRIES — ASSUMPTIONS (Single Source of Truth)
A2: ALL HARDCODED INPUTS LIVE ON THIS SHEET — other sheets reference these cells via formulas
B4: Assumption / Driver | C4: FY22A | D4: FY23A | E4: FY24A | F4: FY25A | G4: FY26A | H4: FY27E | I4: FY28E | J4: FY29E | K4: Notes
B5: 1. REVENUE (₹ Cr) — Standalone
B6: Total Revenue | C6: 3339 | D6: 4104 | E6: 4312 | F6: 4942 | G6: 5443 | H6: 6097 | I6: 6830 | J6: 7650 | K6: FY22-26 = actuals; FY27-29 = analyst estimates
B7: Home Appliances Revenue | C7: 2720 | D7: 3416 | E7: 3609 | F7: 4086 | G7: 4362 | H7: 4900 | I7: 5500 | J7: 6160 | K7: ~80% of total; includes WM, AC, Dishwasher, Microwave, Service
B8: Engineering Revenue | C8: 619 | D8: 688 | E8: 703 | F8: 856 | G8: 880 | H8: 990 | I8: 1109 | J8: 1242 | K8: Fine-blanked components for auto & electricals OEMs
B9: Other / Adjustments | C9: 0 | D9: 0 | E9: 0 | F9: 0 | G9: 201 | H9: 207 | I9: 221 | J9: 248 | K9: Motor segment & inter-segment adjustments
B11: 2. MARGIN ASSUMPTIONS
B12: Gross Margin % | C12: 0.216 | D12: 0.24 | E12: 0.268 | F12: 0.283 | G12: 0.28 | H12: 0.29 | I12: 0.295 | J12: 0.3 | K12: Revenue minus raw materials
B13: Employee Cost % of Revenue | C13: 0.089 | D13: 0.083 | E13: 0.081 | F13: 0.079 | G13: 0.08 | H13: 0.078 | I13: 0.077 | J13: 0.075
B14: Other Opex % of Revenue | C14: 0.057 | D14: 0.053 | E14: 0.06 | F14: 0.06 | G14: 0.06 | H14: 0.062 | I14: 0.06 | J14: 0.058
B15: Other Income (₹ Cr) | C15: 28 | D15: 26 | E15: 32 | F15: 35 | G15: 30 | H15: 32 | I15: 36 | J15: 40 | K15: Interest income, forex, misc
B17: 3. CAPEX, DEPRECIATION & INTEREST (₹ Cr)
B18: Depreciation & Amortisation | C18: 113 | D18: 119 | E18: 122 | F18: 129 | G18: 123 | H18: 135 | I18: 150 | J18: 165 | K18: Actuals; projections ~2% of revenue
B19: Capital Expenditure | C19: 126 | D19: 166 | E19: 154 | F19: 189 | G19: 210 | H19: 230 | I19: 250 | J19: 270 | K19: Maintenance + growth capex
B20: Finance Costs (Interest) | C20: 34 | D20: 33 | E20: 30 | F20: 27 | G20: 24 | H20: 24 | I20: 21 | J20: 18 | K20: Reducing as debt is repaid
B22: 4. TAX & BOOK ADJUSTMENTS
B23: Effective Tax Rate % | C23: -0.33 | D23: 0.5 | E23: 0.24 | F23: 0.25 | G23: 0.25 | H23: 0.26 | I23: 0.26 | J23: 0.26 | K23: FY22 neg due to deferred tax reversal; FY23 spike due to loss c/f expiry
B24: Exceptional Items (₹ Cr) | C24: 0 | D24: 0 | E24: 0 | F24: 0 | G24: 14 | H24: 0 | I24: 0 | J24: 0 | K24: FY26: Labour code incremental liability (₹13.96 Cr annual)
B26: 5. WORKING CAPITAL ASSUMPTIONS (Days)
B27: Debtor Days | C27: 32 | D27: 35 | E27: 37 | F27: 30 | G27: 30 | H27: 30 | I27: 29 | J27: 29
B28: Inventory Days | C28: 104 | D28: 83 | E28: 77 | F28: 81 | G28: 80 | H28: 79 | I28: 78 | J28: 77
B29: Payable Days | C29: 145 | D29: 119 | E29: 137 | F29: 113 | G29: 115 | H29: 115 | I29: 115 | J29: 115
B31: 6. BALANCE SHEET — HISTORICAL ACTUALS (₹ Cr)
B32: Equity Capital | C32: 41 | D32: 41 | E32: 41 | F32: 41 | G32: 41 | H32: 41 | I32: 41 | J32: 41
B33: Reserves & Surplus | C33: 596 | D33: 615 | E33: 685 | F33: 817 | G33: 893 | H33: 1074 | I33: 1305 | J33: 1601 | K33: Prior year + PAT; projected = prev + PAT
B34: Long-Term Borrowings | C34: 188 | D34: 168 | E34: 50 | F34: 130 | G34: 80 | H34: 70 | I34: 60 | J34: 50
B35: Short-Term Borrowings | C35: 169 | D35: 180 | E35: 112 | F35: 119 | G35: 84 | H35: 90 | I35: 80 | J35: 70
B36: Net Block (Fixed Assets) | C36: 672 | D36: 669 | E36: 606 | F36: 671 | G36: 651 | H36: 703 | I36: 803 | J36: 908 | K36: Prior year + Capex - Dep for projections
B37: Investments (NC) | C37: 251 | D37: 210 | E37: 311 | F37: 321 | G37: 347 | H37: 360 | I37: 395 | J37: 430
B38: Cash & Equivalents | C38: 72 | D38: 65 | E38: 92 | F38: 71 | G38: 65 | H38: 82 | I38: 166 | J38: 306 | K38: Closing cash from cash flow
B39: Short-Term Investments | C39: 90 | D39: 120 | E39: 130 | F39: 145 | G39: 155 | H39: 170 | I39: 200 | J39: 250
B40: Other Current Assets | C40: 584 | D40: 583 | E40: 484 | F40: 549 | G40: 463 | H40: 434 | I40: 386 | J40: 344
B41: Other Current Liabilities | C41: 381 | D41: 437 | E41: 495 | F41: 654 | G41: 669 | H41: 730 | I41: 800 | J41: 870
B42: Other Non-Current Liabilities | C42: 438 | D42: 402 | E42: 295 | F42: 349 | G42: 342 | H42: 337 | I42: 333 | J42: 330 | K42: Deferred tax + other NC liabilities
B44: 7. VALUATION INPUTS
B45: WACC % | C45: 0.122 | K45: Cost of equity ~13.5%; Kd ~8%; target D/E 0.15x
B46: Terminal Growth Rate % | C46: 0.055 | K46: Nominal GDP growth proxy; India LT growth ~6-7%
B47: Net Debt FY26A (₹ Cr) | C47: 127
...

Sheet P&L
A1: IFB INDUSTRIES — INCOME STATEMENT (P&L)
A2: Standalone Financials | ₹ Crores | All figures are formulas linked to Assumptions
B4: Line Item | C4: FY22A | D4: FY23A | E4: FY24A | F4: FY25A | G4: FY26A | H4: FY27E | I4: FY28E | J4: FY29E
B5: REVENUE
B6: Net Revenue from Operations | C6: =Assumptions!C6 -> 3339 | D6: =Assumptions!D6 -> 4104 | E6: =Assumptions!E6 -> 4312 | F6: =Assumptions!F6 -> 4942 | G6: =Assumptions!G6 -> 5443 | H6: =Assumptions!H6 -> 6097 | I6: =Assumptions!I6 -> 6830 | J6: =Assumptions!J6 -> 7650
B7: Other Income | C7: =Assumptions!C15 -> 28 | D7: =Assumptions!D15 -> 26 | E7: =Assumptions!E15 -> 32 | F7: =Assumptions!F15 -> 35 | G7: =Assumptions!G15 -> 30 | H7: =Assumptions!H15 -> 32 | I7: =Assumptions!I15 -> 36 | J7: =Assumptions!J15 -> 40
B8: Total Income | C8: =C6+C7 -> 3367 | D8: =D6+D7 -> 4130 | E8: =E6+E7 -> 4344 | F8: =F6+F7 -> 4977 | G8: =G6+G7 -> 5473 | H8: =H6+H7 -> 6129 | I8: =I6+I7 -> 6866 | J8: =J6+J7 -> 7690
B9: Revenue Growth YoY % | C9: - | D9: =(D6-C6)/C6 -> 0.22911051 | E9: =(E6-D6)/D6 -> 0.050682261 | F9: =(F6-E6)/E6 -> 0.1461039 | G9: =(G6-F6)/F6 -> 0.10137596 | H9: =(H6-G6)/G6 -> 0.12015433 | I9: =(I6-H6)/H6 -> 0.12022306 | J9: =(J6-I6)/I6 -> 0.12005857
B10: OPERATING EXPENSES
B11: Raw Material / COGS | C11: =C6*(1-Assumptions!C12) -> 2617.776 | D11: =D6*(1-Assumptions!D12) -> 3119.04 | E11: =E6*(1-Assumptions!E12) -> 3156.384 | F11: =F6*(1-Assumptions!F12) -> 3543.414 | G11: =G6*(1-Assumptions!G12) -> 3918.96 | H11: =H6*(1-Assumptions!H12) -> 4328.87 | I11: =I6*(1-Assumptions!I12) -> 4815.15 | J11: =J6*(1-Assumptions!J12) -> 5355
B12: Employee Benefit Expenses | C12: =C6*Assumptions!C13 -> 297.171 | D12: =D6*Assumptions!D13 -> 340.632 | E12: =E6*Assumptions!E13 -> 349.272 | F12: =F6*Assumptions!F13 -> 390.418 | G12: =G6*Assumptions!G13 -> 435.44 | H12: =H6*Assumptions!H13 -> 475.566 | I12: =I6*Assumptions!I13 -> 525.91 | J12: =J6*Assumptions!J13 -> 573.75
B13: Other Operating Expenses | C13: =C6*Assumptions!C14 -> 190.323 | D13: =D6*Assumptions!D14 -> 217.512 | E13: =E6*Assumptions!E14 -> 258.72 | F13: =F6*Assumptions!F14 -> 296.52 | G13: =G6*Assumptions!G14 -> 326.58 | H13: =H6*Assumptions!H14 -> 378.014 | I13: =I6*Assumptions!I14 -> 409.8 | J13: =J6*Assumptions!J14 -> 443.7
B14: Total Operating Expenses (ex-D&A) | C14: =C11+C12+C13 -> 3105.27 | D14: =D11+D12+D13 -> 3677.184 | E14: =E11+E12+E13 -> 3764.376 | F14: =F11+F12+F13 -> 4230.352 | G14: =G11+G12+G13 -> 4680.98 | H14: =H11+H12+H13 -> 5182.45 | I14: =I11+I12+I13 -> 5750.86 | J14: =J11+J12+J13 -> 6372.45
B15: PROFITABILITY
B16: EBITDA | C16: =C6-C14 -> 233.73 | D16: =D6-D14 -> 426.816 | E16: =E6-E14 -> 547.624 | F16: =F6-F14 -> 711.648 | G16: =G6-G14 -> 762.02 | H16: =H6-H14 -> 914.55 | I16: =I6-I14 -> 1079.14 | J16: =J6-J14 -> 1277.55
B17: EBITDA Margin % | C17: =C16/C6 -> 0.07 | D17: =D16/D6 -> 0.104 | E17: =E16/E6 -> 0.127 | F17: =F16/F6 -> 0.144 | G17: =G16/G6 -> 0.14 | H17: =H16/H6 -> 0.15 | I17: =I16/I6 -> 0.158 | J17: =J16/J6 -> 0.167
B18: (-) Depreciation & Amortisation | C18: =Assumptions!C18 -> 113 | D18: =Assumptions!D18 -> 119 | E18: =Assumptions!E18 -> 122 | F18: =Assumptions!F18 -> 129 | G18: =Assumptions!G18 -> 123 | H18: =Assumptions!H18 -> 135 | I18: =Assumptions!I18 -> 150 | J18: =Assumptions!J18 -> 165
B19: EBIT (Operating Profit) | C19: =C16-C18 -> 120.73 | D19: =D16-D18 -> 307.816 | E19: =E16-E18 -> 425.624 | F19: =F16-F18 -> 582.648 | G19: =G16-G18 -> 639.02 | H19: =H16-H18 -> 779.55 | I19: =I16-I18 -> 929.14 | J19: =J16-J18 -> 1112.55
B20: EBIT Margin % | C20: =C19/C6 -> 0.036157532 | D20: =D19/D6 -> 0.075003899 | E20: =E19/E6 -> 0.098706865 | F20: =F19/F6 -> 0.11789721 | G20: =G19/G6 -> 0.11740217 | H20: =H19/H6 -> 0.12785796 | I20: =I19/I6 -> 0.13603807 | J20: =J19/J6 -> 0.14543137
B21: (-) Finance Costs (Interest) | C21: =Assumptions!C20 -> 34 | D21: =Assumptions!D20 -> 33 | E21: =Assumptions!E20 -> 30 | F21: =Assumptions!F20 -> 27 | G21: =Assumptions!G20 -> 24 | H21: =Assumptions!H20 -> 24 | I21: =Assumptions!I20 -> 21 | J21: =Assumptions!J20 -> 18
B22: (-) Exceptional Items | C22: =Assumptions!C24 -> 0 | D22: =Assumptions!D24 -> 0 | E22: =Assumptions!E24 -> 0 | F22: =Assumptions!F24 -> 0 | G22: =Assumptions!G24 -> 14 | H22: =Assumptions!H24 -> 0 | I22: =Assumptions!I24 -> 0 | J22: =Assumptions!J24 -> 0
B23: Profit Before Tax (PBT) | C23: =C19-C21-C22+C7 -> 114.73 | D23: =D19-D21-D22+D7 -> 300.816 | E23: =E19-E21-E22+E7 -> 427.624 | F23: =F19-F21-F22+F7 -> 590.648 | G23: =G19-G21-G22+G7 -> 631.02 | H23: =H19-H21-H22+H7 -> 787.55 | I23: =I19-I21-I22+I7 -> 944.14 | J23: =J19-J21-J22+J7 -> 1134.55
B24: PBT Margin % | C24: =C23/C6 -> 0.034360587 | D24: =D23/D6 -> 0.073298246 | E24: =E23/E6 -> 0.099170686 | F24: =F23/F6 -> 0.11951599 | G24: =G23/G6 -> 0.11593239 | H24: =H23/H6 -> 0.12917008 | I24: =I23/I6 -> 0.13823426 | J24: =J23/J6 -> 0.14830719
B25: (-) Income Tax | C25: =IF(C23>0,C23*Assumptions!C23,0) -> -37.8609 | D25: =IF(D23>0,D23*Assumptions!D23,0) -> 150.408 | E25: =IF(E23>0,E23*Assumptions!E23,0) -> 102.62976 | F25: =IF(F23>0,F23*Assumptions!F23,0) -> 147.662 | G25: =IF(G23>0,G23*Assumptions!G23,0) -> 157.755 | H25: =IF(H23>0,H23*Assumptions!H23,0) -> 204.763 | I25: =IF(I23>0,I23*Assumptions!I23,0) -> 245.4764 | J25: =IF(J23>0,J23*Assumptions!J23,0) -> 294.983
B26: PAT — Net Profit | C26: =C23-C25 -> 152.5909 | D26: =D23-D25 -> 150.408 | E26: =E23-E25 -> 324.99424 | F26: =F23-F25 -> 442.986 | G26: =G23-G25 -> 473.265 | H26: =H23-H25 -> 582.787 | I26: =I23-I25 -> 698.6636 | J26: =J23-J25 -> 839.567
B27: PAT Margin % | C27: =C26/C6 -> 0.045699581 | D27: =D26/D6 -> 0.036649123 | E27: =E26/E6 -> 0.075369722 | F27: =F26/F6 -> 0.089636989 | G27: =G26/G6 -> 0.086949293 | H27: =H26/H6 -> 0.095585862 | I27: =I26/I6 -> 0.10229335 | J27: =J26/J6 -> 0.10974732
B28: PER SHARE METRICS
B29: EPS (₹ per share) | C29: =C26/Assumptions!C48 -> 37.491622 | D29: =D26/Assumptions!C48 -> 36.955283 | E29: =E26/Assumptions!C48 -> 79.851165 | F29: =F26/Assumptions!C48 -> 108.84177 | G29: =G26/Assumptions!C48 -> 116.28133 | H29: =H26/Assumptions!C48 -> 143.19091 | I29: =I26/Assumptions!C48 -> 171.66182 | J29: =J26/Assumptions!C48 -> 206.28182

Sheet BalanceSheet
A1: IFB INDUSTRIES — BALANCE SHEET
A2: All projected figures linked to Assumptions | ₹ Crores
B4: Line Item | C4: FY22A | D4: FY23A | E4: FY24A | F4: FY25A | G4: FY26A | H4: FY27E | I4: FY28E | J4: FY29E
B5: EQUITY & LIABILITIES
B6: Share Capital | C6: =Assumptions!C32 -> 41 | D6: =Assumptions!D32 -> 41 | E6: =Assumptions!E32 -> 41 | F6: =Assumptions!F32 -> 41 | G6: =Assumptions!G32 -> 41 | H6: =Assumptions!H32 -> 41 | I6: =Assumptions!I32 -> 41 | J6: =Assumptions!J32 -> 41
B7: Reserves & Surplus | C7: =Assumptions!C33 -> 596 | D7: =Assumptions!D33 -> 615 | E7: =Assumptions!E33 -> 685 | F7: =Assumptions!F33 -> 817 | G7: =Assumptions!G33 -> 893 | H7: =Assumptions!H33 -> 1074 | I7: =Assumptions!I33 -> 1305 | J7: =Assumptions!J33 -> 1601
B8: TOTAL EQUITY | C8: =C6+C7 -> 637 | D8: =D6+D7 -> 656 | E8: =E6+E7 -> 726 | F8: =F6+F7 -> 858 | G8: =G6+G7 -> 934 | H8: =H6+H7 -> 1115 | I8: =I6+I7 -> 1346 | J8: =J6+J7 -> 1642
B9: Long-Term Borrowings | C9: =Assumptions!C34 -> 188 | D9: =Assumptions!D34 -> 168 | E9: =Assumptions!E34 -> 50 | F9: =Assumptions!F34 -> 130 | G9: =Assumptions!G34 -> 80 | H9: =Assumptions!H34 -> 70 | I9: =Assumptions!I34 -> 60 | J9: =Assumptions!J34 -> 50
B10: Other Non-Current Liabilities (incl. Def. Tax) | C10: =Assumptions!C42 -> 438 | D10: =Assumptions!D42 -> 402 | E10: =Assumptions!E42 -> 295 | F10: =Assumptions!F42 -> 349 | G10: =Assumptions!G42 -> 342 | H10: =Assumptions!H42 -> 337 | I10: =Assumptions!I42 -> 333 | J10: =Assumptions!J42 -> 330
B11: TOTAL NON-CURRENT LIABILITIES | C11: =C9+C10 -> 626 | D11: =D9+D10 -> 570 | E11: =E9+E10 -> 345 | F11: =F9+F10 -> 479 | G11: =G9+G10 -> 422 | H11: =H9+H10 -> 407 | I11: =I9+I10 -> 393 | J11: =J9+J10 -> 380
B12: Short-Term Borrowings | C12: =Assumptions!C35 -> 169 | D12: =Assumptions!D35 -> 180 | E12: =Assumptions!E35 -> 112 | F12: =Assumptions!F35 -> 119 | G12: =Assumptions!G35 -> 84 | H12: =Assumptions!H35 -> 90 | I12: =Assumptions!I35 -> 80 | J12: =Assumptions!J35 -> 70
B13: Trade Payables | C13: ='P&L'!C11*Assumptions!C29/365 -> 1039.9384 | D13: ='P&L'!D11*Assumptions!D29/365 -> 1016.8925 | E13: ='P&L'!E11*Assumptions!E29/365 -> 1184.725 | F13: ='P&L'!F11*Assumptions!F29/365 -> 1097.0021 | G13: ='P&L'!G11*Assumptions!G29/365 -> 1234.7408 | H13: ='P&L'!H11*Assumptions!H29/365 -> 1363.8905 | I13: ='P&L'!I11*Assumptions!I29/365 -> 1517.1021 | J13: ='P&L'!J11*Assumptions!J29/365 -> 1687.1918
B14: Other Current Liabilities | C14: =Assumptions!C41 -> 381 | D14: =Assumptions!D41 -> 437 | E14: =Assumptions!E41 -> 495 | F14: =Assumptions!F41 -> 654 | G14: =Assumptions!G41 -> 669 | H14: =Assumptions!H41 -> 730 | I14: =Assumptions!I41 -> 800 | J14: =Assumptions!J41 -> 870
B15: TOTAL CURRENT LIABILITIES | C15: =C12+C13+C14 -> 1589.9384 | D15: =D12+D13+D14 -> 1633.8925 | E15: =E12+E13+E14 -> 1791.725 | F15: =F12+F13+F14 -> 1870.0021 | G15: =G12+G13+G14 -> 1987.7408 | H15: =H12+H13+H14 -> 2183.8905 | I15: =I12+I13+I14 -> 2397.1021 | J15: =J12+J13+J14 -> 2627.1918
B16: TOTAL EQUITY + LIABILITIES | C16: =C8+C11+C15 -> 2852.9384 | D16: =D8+D11+D15 -> 2859.8925 | E16: =E8+E11+E15 -> 2862.725 | F16: =F8+F11+F15 -> 3207.0021 | G16: =G8+G11+G15 -> 3343.7408 | H16: =H8+H11+H15 -> 3705.8905 | I16: =I8+I11+I15 -> 4136.1021 | J16: =J8+J11+J15 -> 4649.1918
B18: ASSETS
B19: Net Block (Fixed Assets) | C19: =Assumptions!C36 -> 672 | D19: =Assumptions!D36 -> 669 | E19: =Assumptions!E36 -> 606 | F19: =Assumptions!F36 -> 671 | G19: =Assumptions!G36 -> 651 | H19: =Assumptions!H36 -> 703 | I19: =Assumptions!I36 -> 803 | J19: =Assumptions!J36 -> 908
B20: Investments (Non-Current) | C20: =Assumptions!C37 -> 251 | D20: =Assumptions!D37 -> 210 | E20: =Assumptions!E37 -> 311 | F20: =Assumptions!F37 -> 321 | G20: =Assumptions!G37 -> 347 | H20: =Assumptions!H37 -> 360 | I20: =Assumptions!I37 -> 395 | J20: =Assumptions!J37 -> 430
B21: Other Non-Current Assets (CWIP + Intangibles) | C21: 33 | D21: 38 | E21: 31 | F21: 27 | G21: 36 | H21: 33 | I21: 30 | J21: 27
B22: TOTAL NON-CURRENT ASSETS | C22: =C19+C20+C21 -> 956 | D22: =D19+D20+D21 -> 917 | E22: =E19+E20+E21 -> 948 | F22: =F19+F20+F21 -> 1019 | G22: =G19+G20+G21 -> 1034 | H22: =H19+H20+H21 -> 1096 | I22: =I19+I20+I21 -> 1228 | J22: =J19+J20+J21 -> 1365
B23: Inventories | C23: ='P&L'!C11*Assumptions!C28/365 -> 745.88686 | D23: ='P&L'!D11*Assumptions!D28/365 -> 709.26115 | E23: ='P&L'!E11*Assumptions!E28/365 -> 665.86731 | F23: ='P&L'!F11*Assumptions!F28/365 -> 786.34667 | G23: ='P&L'!G11*Assumptions!G28/365 -> 858.95014 | H23: ='P&L'!H11*Assumptions!H28/365 -> 936.93351 | I23: ='P&L'!I11*Assumptions!I28/365 -> 1028.991 | J23: ='P&L'!J11*Assumptions!J28/365 -> 1129.6849
B24: Trade Receivables | C24: ='P&L'!C6*Assumptions!C27/365 -> 292.73425 | D24: ='P&L'!D6*Assumptions!D27/365 -> 393.53425 | E24: ='P&L'!E6*Assumptions!E27/365 -> 437.10685 | F24: ='P&L'!F6*Assumptions!F27/365 -> 406.19178 | G24: ='P&L'!G6*Assumptions!G27/365 -> 447.36986 | H24: ='P&L'!H6*Assumptions!H27/365 -> 501.12329 | I24: ='P&L'!I6*Assumptions!I27/365 -> 542.65753 | J24: ='P&L'!J6*Assumptions!J27/365 -> 607.80822
B25: Cash & Cash Equivalents | C25: =Assumptions!C38 -> 72 | D25: =Assumptions!D38 -> 65 | E25: =Assumptions!E38 -> 92 | F25: =Assumptions!F38 -> 71 | G25: =Assumptions!G38 -> 65 | H25: =Assumptions!H38 -> 82 | I25: =Assumptions!I38 -> 166 | J25: =Assumptions!J38 -> 306
B26: Short-Term Investments | C26: =Assumptions!C39 -> 90 | D26: =Assumptions!D39 -> 120 | E26: =Assumptions!E39 -> 130 | F26: =Assumptions!F39 -> 145 | G26: =Assumptions!G39 -> 155 | H26: =Assumptions!H39 -> 170 | I26: =Assumptions!I39 -> 200 | J26: =Assumptions!J39 -> 250
B27: Other Current Assets | C27: =Assumptions!C40 -> 584 | D27: =Assumptions!D40 -> 583 | E27: =Assumptions!E40 -> 484 | F27: =Assumptions!F40 -> 549 | G27: =Assumptions!G40 -> 463 | H27: =Assumptions!H40 -> 434 | I27: =Assumptions!I40 -> 386 | J27: =Assumptions!J40 -> 344
B28: TOTAL CURRENT ASSETS | C28: =C23+C24+C25+C26+C27 -> 1784.6211 | D28: =D23+D24+D25+D26+D27 -> 1870.7954 | E28: =E23+E24+E25+E26+E27 -> 1808.9742 | F28: =F23+F24+F25+F26+F27 -> 1957.5384 | G28: =G23+G24+G25+G26+G27 -> 1989.32 | H28: =H23+H24+H25+H26+H27 -> 2124.0568 | I28: =I23+I24+I25+I26+I27 -> 2323.6485 | J28: =J23+J24+J25+J26+J27 -> 2637.4932
B29: TOTAL ASSETS | C29: =C22+C28 -> 2740.6211 | D29: =D22+D28 -> 2787.7954 | E29: =E22+E28 -> 2756.9742 | F29: =F22+F28 -> 2976.5384 | G29: =G22+G28 -> 3023.32 | H29: =H22+H28 -> 3220.0568 | I29: =I22+I28 -> 3551.6485 | J29: =J22+J28 -> 4002.4932
B30: CHECK: Assets – (Equity+Liabilities) = 0? | C30: =C29-C16 -> -112.3173 | D30: =D29-D16 -> -72.097096 | E30: =E29-E16 -> -105.75079 | F30: =F29-F16 -> -230.46369 | G30: =G29-G16 -> -320.42082 | H30: =H29-H16 -> -485.83375 | I30: =I29-I16 -> -584.45356 | J30: =J29-J16 -> -646.69863

Sheet CashFlow
A1: IFB INDUSTRIES — CASH FLOW STATEMENT
A2: All figures are formulas from P&L and Balance Sheet | ₹ Crores
B4: Line Item | C4: FY22A | D4: FY23A | E4: FY24A | F4: FY25A | G4: FY26A | H4: FY27E | I4: FY28E | J4: FY29E
B5: A. OPERATING ACTIVITIES (INDIRECT METHOD)
B6: Net Profit (PAT) | C6: ='P&L'!C26 -> 152.5909 | D6: ='P&L'!D26 -> 150.408 | E6: ='P&L'!E26 -> 324.99424 | F6: ='P&L'!F26 -> 442.986 | G6: ='P&L'!G26 -> 473.265 | H6: ='P&L'!H26 -> 582.787 | I6: ='P&L'!I26 -> 698.6636 | J6: ='P&L'!J26 -> 839.567
B7: (+) Depreciation & Amortisation | C7: =Assumptions!C18 -> 113 | D7: =Assumptions!D18 -> 119 | E7: =Assumptions!E18 -> 122 | F7: =Assumptions!F18 -> 129 | G7: =Assumptions!G18 -> 123 | H7: =Assumptions!H18 -> 135 | I7: =Assumptions!I18 -> 150 | J7: =Assumptions!J18 -> 165
B8: (+) Finance Costs Added Back | C8: =Assumptions!C20 -> 34 | D8: =Assumptions!D20 -> 33 | E8: =Assumptions!E20 -> 30 | F8: =Assumptions!F20 -> 27 | G8: =Assumptions!G20 -> 24 | H8: =Assumptions!H20 -> 24 | I8: =Assumptions!I20 -> 21 | J8: =Assumptions!J20 -> 18
B9: (+/-) Changes in Working Capital | C9: - | D9: =(BalanceSheet!C24-BalanceSheet!D24)+(BalanceSheet!C23-BalanceSheet!D23)+(BalanceSheet!D13-BalanceSheet!C13) -> -87.220208 | E9: =(BalanceSheet!D24-BalanceSheet!E24)+(BalanceSheet!D23-BalanceSheet!E23)+(BalanceSheet!E13-BalanceSheet!D13) -> 167.6537 | F9: =(BalanceSheet!E24-BalanceSheet!F24)+(BalanceSheet!E23-BalanceSheet!F23)+(BalanceSheet!F13-BalanceSheet!E13) -> -177.2871 | G9: =(BalanceSheet!F24-BalanceSheet!G24)+(BalanceSheet!F23-BalanceSheet!G23)+(BalanceSheet!G13-BalanceSheet!F13) -> 23.957129 | H9: =(BalanceSheet!G24-BalanceSheet!H24)+(BalanceSheet!G23-BalanceSheet!H23)+(BalanceSheet!H13-BalanceSheet!G13) -> -2.5870685 | I9: =(BalanceSheet!H24-BalanceSheet!I24)+(BalanceSheet!H23-BalanceSheet!I23)+(BalanceSheet!I13-BalanceSheet!H13) -> 19.619808 | J9: =(BalanceSheet!I24-BalanceSheet!J24)+(BalanceSheet!I23-BalanceSheet!J23)+(BalanceSheet!J13-BalanceSheet!I13) -> 4.2450685
B10: (-) Tax Paid | C10: =-'P&L'!C25 -> 37.8609 | D10: =-'P&L'!D25 -> -150.408 | E10: =-'P&L'!E25 -> -102.62976 | F10: =-'P&L'!F25 -> -147.662 | G10: =-'P&L'!G25 -> -157.755 | H10: =-'P&L'!H25 -> -204.763 | I10: =-'P&L'!I25 -> -245.4764 | J10: =-'P&L'!J25 -> -294.983
B11: (-) Finance Costs Paid | C11: =-Assumptions!C20 -> -34 | D11: =-Assumptions!D20 -> -33 | E11: =-Assumptions!E20 -> -30 | F11: =-Assumptions!F20 -> -27 | G11: =-Assumptions!G20 -> -24 | H11: =-Assumptions!H20 -> -24 | I11: =-Assumptions!I20 -> -21 | J11: =-Assumptions!J20 -> -18
B12: CASH FROM OPERATIONS (CFO) | C12: =C6+C7+C8+C10+C11 -> 303.4518 | D12: =D6+D7+D8+D9+D10+D11 -> 31.779792 | E12: =E6+E7+E8+E9+E10+E11 -> 512.01818 | F12: =F6+F7+F8+F9+F10+F11 -> 247.0369 | G12: =G6+G7+G8+G9+G10+G11 -> 462.46713 | H12: =H6+H7+H8+H9+H10+H11 -> 510.43693 | I12: =I6+I7+I8+I9+I10+I11 -> 622.80701 | J12: =J6+J7+J8+J9+J10+J11 -> 713.82907
B14: B. INVESTING ACTIVITIES
B15: (-) Capital Expenditure | C15: =-Assumptions!C19 -> -126 | D15: =-Assumptions!D19 -> -166 | E15: =-Assumptions!E19 -> -154 | F15: =-Assumptions!F19 -> -189 | G15: =-Assumptions!G19 -> -210 | H15: =-Assumptions!H19 -> -230 | I15: =-Assumptions!I19 -> -250 | J15: =-Assumptions!J19 -> -270
B16: (+/-) Net Change in Investments & Asset Sales | C16: 10 | D16: 5 | E16: 5 | F16: 5 | G16: 5 | H16: 5 | I16: 5 | J16: 5
B17: CASH FROM INVESTING (CFI) | C17: =C15+C16 -> -116 | D17: =D15+D16 -> -161 | E17: =E15+E16 -> -149 | F17: =F15+F16 -> -184 | G17: =G15+G16 -> -205 | H17: =H15+H16 -> -225 | I17: =I15+I16 -> -245 | J17: =J15+J16 -> -265
B19: C. FINANCING ACTIVITIES
B20: (+/-) Net Borrowings (Raised / Repaid) | C20: - | D20: =(BalanceSheet!D9-BalanceSheet!C9)+(BalanceSheet!D12-BalanceSheet!C12) -> -9 | E20: =(BalanceSheet!E9-BalanceSheet!D9)+(BalanceSheet!E12-BalanceSheet!D12) -> -186 | F20: =(BalanceSheet!F9-BalanceSheet!E9)+(BalanceSheet!F12-BalanceSheet!E12) -> 87 | G20: =(BalanceSheet!G9-BalanceSheet!F9)+(BalanceSheet!G12-BalanceSheet!F12) -> -85 | H20: =(BalanceSheet!H9-BalanceSheet!G9)+(BalanceSheet!H12-BalanceSheet!G12) -> -4 | I20: =(BalanceSheet!I9-BalanceSheet!H9)+(BalanceSheet!I12-BalanceSheet!H12) -> -20 | J20: =(BalanceSheet!J9-BalanceSheet!I9)+(BalanceSheet!J12-BalanceSheet!I12) -> -20
B21: (-) Dividends Paid | C21: 0 | D21: 0 | E21: 0 | F21: 0 | G21: 0 | H21: 0 | I21: 0 | J21: 0
B22: CASH FROM FINANCING (CFF) | C22: =IF(ISNUMBER(C20),C20,0)+C21-C11 -> 34 | D22: =D20+D21-D11 -> 24 | E22: =E20+E21-E11 -> -156 | F22: =F20+F21-F11 -> 114 | G22: =G20+G21-G11 -> -61 | H22: =H20+H21-H11 -> 20 | I22: =I20+I21-I11 -> 1 | J22: =J20+J21-J11 -> -2
B24: D. FREE CASH FLOW SUMMARY
B25: FREE CASH FLOW (FCF = CFO + Capex) | C25: =C12+C15 -> 177.4518 | D25: =D12+D15 -> -134.22021 | E25: =E12+E15 -> 358.01818 | F25: =F12+F15 -> 58.036899 | G25: =G12+G15 -> 252.46713 | H25: =H12+H15 -> 280.43693 | I25: =I12+I15 -> 372.80701 | J25: =J12+J15 -> 443.82907
B26: FCF Margin % | C26: =C25/'P&L'!C6 -> 0.053145193 | D26: =D25/'P&L'!D6 -> -0.032704729 | E26: =E25/'P&L'!E6 -> 0.083028335 | F26: =F25/'P&L'!F6 -> 0.011743606 | G26: =G25/'P&L'!G6 -> 0.046383819 | H26: =H25/'P&L'!H6 -> 0.045995888 | I26: =I25/'P&L'!I6 -> 0.054583749 | J26: =J25/'P&L'!J6 -> 0.058016872
B27: CFO / EBITDA | C27: =IF('P&L'!C16<>0,C12/'P&L'!C16,0) -> 1.2983006 | D27: =IF('P&L'!D16<>0,D12/'P&L'!D16,0) -> 0.074457827 | E27: =IF('P&L'!E16<>0,E12/'P&L'!E16,0) -> 0.93498126 | F27: =IF('P&L'!F16<>0,F12/'P&L'!F16,0) -> 0.34713355 | G27: =IF('P&L'!G16<>0,G12/'P&L'!G16,0) -> 0.60689631 | H27: =IF('P&L'!H16<>0,H12/'P&L'!H16,0) -> 0.55812906 | I27: =IF('P&L'!I16<>0,I12/'P&L'!I16,0) -> 0.57713272 | J27: =IF('P&L'!J16<>0,J12/'P&L'!J16,0) -> 0.55874844

Sheet DCF
A1: IFB INDUSTRIES — DCF VALUATION
A2: FCFF-based intrinsic value | All cells are formulas referencing Assumptions and P&L
B4: INPUTS PULLED FROM ASSUMPTIONS SHEET
B5: WACC % | C5: =Assumptions!C45 -> 0.122
B6: Terminal Growth Rate % | C6: =Assumptions!C46 -> 0.055
B7: Net Debt (₹ Cr) | C7: =Assumptions!C47 -> 127
B8: Shares Outstanding | C8: =Assumptions!C48 -> 4.07
B9: Effective Tax Rate % | C9: =Assumptions!J23 -> 0.26
B12: FREE CASH FLOW TO FIRM (FCFF) — FY27E to FY31E
B13: Line Item | C13: FY27E | D13: FY28E | E13: FY29E | F13: FY30E | G13: FY31E
B14: EBIT (₹ Cr) | C14: ='P&L'!H19 -> 779.55 | D14: ='P&L'!I19 -> 929.14 | E14: ='P&L'!J19 -> 1112.55 | F14: =E14*1.1 -> 1223.805 | G14: =F14*1.09 -> 1333.9475
B15: (-) Taxes on EBIT (NOPAT adjustment) | C15: =-C14*C9 -> -202.683 | D15: =-D14*C9 -> -241.5764 | E15: =-E14*C9 -> -289.263 | F15: =-F14*C9 -> -318.1893 | G15: =-G14*C9 -> -346.82634
B16: NOPAT (Net Operating Profit After Tax) | C16: =C14+C15 -> 576.867 | D16: =D14+D15 -> 687.5636 | E16: =E14+E15 -> 823.287 | F16: =F14+F15 -> 905.6157 | G16: =G14+G15 -> 987.12111
B17: (+) Depreciation & Amortisation | C17: =Assumptions!H18 -> 135 | D17: =Assumptions!I18 -> 150 | E17: =Assumptions!J18 -> 165 | F17: =E17*1.07 -> 176.55 | G17: =F17*1.07 -> 188.9085
B18: (-) Capital Expenditure | C18: =-Assumptions!H19 -> -230 | D18: =-Assumptions!I19 -> -250 | E18: =-Assumptions!J19 -> -270 | F18: =E18*1.06 -> -286.2 | G18: =F18*1.06 -> -303.372
B19: (-) Increase in Net Working Capital | C19: -30 | D19: -35 | E19: -40 | F19: -42 | G19: -45
B20: FCFF (₹ Cr) | C20: =C16+C17+C18+C19 -> 451.867 | D20: =D16+D17+D18+D19 -> 552.5636 | E20: =E16+E17+E18+E19 -> 678.287 | F20: =F16+F17+F18+F19 -> 753.9657 | G20: =G16+G17+G18+G19 -> 827.65761
B22: DISCOUNTING & ENTERPRISE VALUE
B23: Discount Period (years) | C23: 1 | D23: 2 | E23: 3 | F23: 4 | G23: 5
B24: Discount Factor (1/(1+WACC)^t) | C24: =1/(1+C5)^C23 -> 0.8912656 | D24: =1/(1+C5)^D23 -> 0.79435436 | E24: =1/(1+C5)^E23 -> 0.70798072 | F24: =1/(1+C5)^F23 -> 0.63099886 | G24: =1/(1+C5)^G23 -> 0.56238757
B25: PV of FCFF (₹ Cr) | C25: =C20*C24 -> 402.73351 | D25: =D20*D24 -> 438.93131 | E25: =E20*E24 -> 480.21412 | F25: =F20*F24 -> 475.75149 | G25: =G20*G24 -> 465.46436
B26: Sum of PV of FCFF (Phase 1) | C26: =SUM(C25:G25) -> 2263.0948
B27: Terminal Value (FCFF_t5*(1+g)/(WACC-g)) | C27: =G20*(1+C6)/(C5-C6) -> 13032.519
B28: PV of Terminal Value | C28: =C27*G24 -> 7329.3268
B29: Enterprise Value (EV) | C29: =C26+C28 -> 9592.4216
B30: (-) Net Debt | C30: =C7 -> 127
B31: Equity Value (₹ Cr) | C31: =C29-C30 -> 9465.4216
B32: INTRINSIC VALUE PER SHARE (₹) | C32: =C31/C8*100 -> 232565.64
B33: Upside / Downside vs CMP | C33: =(C32-Assumptions!C51)/Assumptions!C51 -> 211.0015
B35: SENSITIVITY: INTRINSIC VALUE (₹/share) vs WACC and Terminal Growth Rate
B36: TGR ↓ / WACC → | C36: 0.1 | D36: 0.11 | E36: 0.12 | F36: 0.122 | G36: 0.13
B37: 0.04 | C37: =((C20/(1+0.1)^1+D20/(1+0.1)^2+E20/(1+0.1)^3+F20/(1+0.1)^4+G20/(1+0.1)^5)+((G20*(1+0.04)/(0.1-0.04))/(1+0.1)^5)-C30)/C8*100 -> 274857.89 | D37: =((C20/(1+0.11)^1+D20/(1+0.11)^2+E20/(1+0.11)^3+F20/(1+0.11)^4+G20/(1+0.11)^5)+((G20*(1+0.04)/(0.11-0.04))/(1+0.11)^5)-C30)/C8*100 -> 233656.09 | E37: =((C20/(1+0.12)^1+D20/(1+0.12)^2+E20/(1+0.12)^3+F20/(1+0.12)^4+G20/(1+0.12)^5)+((G20*(1+0.04)/(0.12-0.04))/(1+0.12)^5)-C30)/C8*100 -> 202795.95 | F37: =((C20/(1+0.122)^1+D20/(1+0.122)^2+E20/(1+0.122)^3+F20/(1+0.122)^4+G20/(1+0.122)^5)+((G20*(1+0.04)/(0.122-0.04))/(1+0.122)^5)-C30)/C8*100 -> 197531.82 | G37: =((C20/(1+0.13)^1+D20/(1+0.13)^2+E20/(1+0.13)^3+F20/(1+0.13)^4+G20/(1+0.13)^5)+((G20*(1+0.04)/(0.13-0.04))/(1+0.13)^5)-C30)/C8*100 -> 178828.7
B38: 0.045 | C38: =((C20/(1+0.1)^1+D20/(1+0.1)^2+E20/(1+0.1)^3+F20/(1+0.1)^4+G20/(1+0.1)^5)+((G20*(1+0.045)/(0.1-0.045))/(1+0.1)^5)-C30)/C8*100 -> 295902.54 | D38: =((C20/(1+0.11)^1+D20/(1+0.11)^2+E20/(1+0.11)^3+F20/(1+0.11)^4+G20/(1+0.11)^5)+((G20*(1+0.045)/(0.11-0.045))/(1+0.11)^5)-C30)/C8*100 -> 248376.61 | E38: =((C20/(1+0.12)^1+D20/(1+0.12)^2+E20/(1+0.12)^3+F20/(1+0.12)^4+G20/(1+0.12)^5)+((G20*(1+0.045)/(0.12-0.045))/(1+0.12)^5)-C30)/C8*100 -> 213565.64 | F38: =((C20/(1+0.122)^1+D20/(1+0.122)^2+E20/(1+0.122)^3+F20/(1+0.122)^4+G20/(1+0.122)^5)+((G20*(1+0.045)/(0.122-0.045))/(1+0.122)^5)-C30)/C8*100 -> 207693.15 | G38: =((C20/(1+0.13)^1+D20/(1+0.13)^2+E20/(1+0.13)^3+F20/(1+0.13)^4+G20/(1+0.13)^5)+((G20*(1+0.045)/(0.13-0.045))/(1+0.13)^5)-C30)/C8*100 -> 186980.45
B39: 0.05 | C39: =((C20/(1+0.1)^1+D20/(1+0.1)^2+E20/(1+0.1)^3+F20/(1+0.1)^4+G20/(1+0.1)^5)+((G20*(1+0.05)/(0.1-0.05))/(1+0.1)^5)-C30)/C8*100 -> 321156.11 | D39: =((C20/(1+0.11)^1+D20/(1+0.11)^2+E20/(1+0.11)^3+F20/(1+0.11)^4+G20/(1+0.11)^5)+((G20*(1+0.05)/(0.11-0.05))/(1+0.11)^5)-C30)/C8*100 -> 265550.54 | E39: =((C20/(1+0.12)^1+D20/(1+0.12)^2+E20/(1+0.12)^3+F20/(1+0.12)^4+G20/(1+0.12)^5)+((G20*(1+0.05)/(0.12-0.05))/(1+0.12)^5)-C30)/C8*100 -> 225873.85 | F39: =((C20/(1+0.122)^1+D20/(1+0.122)^2+E20/(1+0.122)^3+F20/(1+0.122)^4+G20/(1+0.122)^5)+((G20*(1+0.05)/(0.122-0.05))/(1+0.122)^5)-C30)/C8*100 -> 219265.77 | G39: =((C20/(1+0.13)^1+D20/(1+0.13)^2+E20/(1+0.13)^3+F20/(1+0.13)^4+G20/(1+0.13)^5)+((G20*(1+0.05)/(0.13-0.05))/(1+0.13)^5)-C30)/C8*100 -> 196151.17
B40: 0.055 | C40: =((C20/(1+0.1)^1+D20/(1+0.1)^2+E20/(1+0.1)^3+F20/(1+0.1)^4+G20/(1+0.1)^5)+((G20*(1+0.055)/(0.1-0.055))/(1+0.1)^5)-C30)/C8*100 -> 352021.59 | D40: =((C20/(1+0.11)^1+D20/(1+0.11)^2+E20/(1+0.11)^3+F20/(1+0.11)^4+G20/(1+0.11)^5)+((G20*(1+0.055)/(0.11-0.055))/(1+0.11)^5)-C30)/C8*100 -> 285847.01 | E40: =((C20/(1+0.12)^1+D20/(1+0.12)^2+E20/(1+0.12)^3+F20/(1+0.12)^4+G20/(1+0.12)^5)+((G20*(1+0.055)/(0.12-0.055))/(1+0.12)^5)-C30)/C8*100 -> 240075.63 | F40: =((C20/(1+0.122)^1+D20/(1+0.122)^2+E20/(1+0.122)^3+F20/(1+0.122)^4+G20/(1+0.122)^5)+((G20*(1+0.055)/(0.122-0.055))/(1+0.122)^5)-C30)/C8*100 -> 232565.64 | G40: =((C20/(1+0.13)^1+D20/(1+0.13)^2+E20/(1+0.13)^3+F20/(1+0.13)^4+G20/(1+0.13)^5)+((G20*(1+0.055)/(0.13-0.055))/(1+0.13)^5)-C30)/C8*100 -> 206544.66
B41: 0.06 | C41: =((C20/(1+0.1)^1+D20/(1+0.1)^2+E20/(1+0.1)^3+F20/(1+0.1)^4+G20/(1+0.1)^5)+((G20*(1+0.06)/(0.1-0.06))/(1+0.1)^5)-C30)/C8*100 -> 390603.45 | D41: =((C20/(1+0.11)^1+D20/(1+0.11)^2+E20/(1+0.11)^3+F20/(1+0.11)^4+G20/(1+0.11)^5)+((G20*(1+0.06)/(0.11-0.06))/(1+0.11)^5)-C30)/C8*100 -> 310202.77 | E41: =((C20/(1+0.12)^1+D20/(1+0.12)^2+E20/(1+0.12)^3+F20/(1+0.12)^4+G20/(1+0.12)^5)+((G20*(1+0.06)/(0.12-0.06))/(1+0.12)^5)-C30)/C8*100 -> 256644.37 | F41: =((C20/(1+0.122)^1+D20/(1+0.122)^2+E20/(1+0.122)^3+F20/(1+0.122)^4+G20/(1+0.122)^5)+((G20*(1+0.06)/(0.122-0.06))/(1+0.122)^5)-C30)/C8*100 -> 248010.66 | G41: =((C20/(1+0.13)^1+D20/(1+0.13)^2+E20/(1+0.13)^3+F20/(1+0.13)^4+G20/(1+0.13)^5)+((G20*(1+0.06)/(0.13-0.06))/(1+0.13)^5)-C30)/C8*100 -> 218422.93

Sheet Comps
A1: IFB INDUSTRIES — PEER COMPARABLES VALUATION
A2: Indian Consumer Durables / Home Appliances Sector | ₹ Crores
B4: Company | C4: Mkt Cap | D4: Revenue | E4: EBITDA | F4: EBITDA% | G4: PAT | H4: PAT% | I4: EV/EBITDA | J4: P/E | K4: P/B | L4: ROCE%
B5: Voltas | C5: 38500 | D5: 11200 | E5: 850 | F5: 0.076 | G5: 600 | H5: 0.054 | I5: 28.5x | J5: 64.2x | K5: 6.8x | L5: 0.142
B6: Havells India | C6: 96000 | D6: 17800 | E6: 2100 | F6: 0.118 | G6: 1550 | H6: 0.087 | I6: 34.2x | J6: 61.9x | K6: 11.2x | L6: 0.248
B7: Blue Star | C7: 23500 | D7: 10600 | E7: 900 | F7: 0.085 | G7: 510 | H7: 0.048 | I7: 19.8x | J7: 46.1x | K7: 7.9x | L7: 0.214
B8: Whirlpool India | C8: 6800 | D8: 7100 | E8: 480 | F8: 0.068 | G8: 260 | H8: 0.037 | I8: 10.9x | J8: 26.2x | K8: 3.1x | L8: 0.118
B9: V-Guard Ind. | C9: 9200 | D9: 5000 | E9: 450 | F9: 0.09 | G9: 300 | H9: 0.06 | I9: 16.5x | J9: 30.7x | K9: 5.2x | L9: 0.186
B10: Crompton CGL | C10: 13200 | D10: 6800 | E10: 680 | F10: 0.1 | G10: 470 | H10: 0.069 | I10: 16.2x | J10: 28.1x | K10: 6.2x | L10: 0.223
B11: Symphony Ltd | C11: 5100 | D11: 1100 | E11: 250 | F11: 0.227 | G11: 190 | H11: 0.173 | I11: 21.4x | J11: 26.8x | K11: 5.6x | L11: 0.302
B12: Bajaj Electric. | C12: 5400 | D12: 5400 | E12: 420 | F12: 0.078 | G12: 250 | H12: 0.046 | I12: 13.1x | J12: 21.6x | K12: 3.8x | L12: 0.147
B13: PEER MEDIAN | C13: =MEDIAN(C5:C12) -> 11200 | D13: =MEDIAN(D5:D12) -> 6950 | E13: =MEDIAN(E5:E12) -> 580 | F13: =MEDIAN(F5:F12) -> 0.0875 | G13: =MEDIAN(G5:G12) -> 385 | H13: =MEDIAN(H5:H12) -> 0.057 | I13: see below | J13: see below | K13: see below | L13: =MEDIAN(L5:L12) -> 0.2
B14: IFB Industries (FY26A) | C14: =Assumptions!C51*Assumptions!C48 -> 4464.79 | D14: ='P&L'!G6 -> 5443 | E14: ='P&L'!G16 -> 762.02 | F14: ='P&L'!G17 -> 0.14 | G14: ='P&L'!G26 -> 473.265 | H14: ='P&L'!G27 -> 0.086949293 | I14: =(C14+Assumptions!C47)/E14 -> 6.025813 | J14: =Assumptions!C51/('P&L'!G29) -> 9.4340169 | K14: =C14/(BalanceSheet!G8) -> 4.7802891 | L14: 0.198
B16: IMPLIED VALUATION (from comps multiples × IFB metrics)
B17: EV/EBITDA Approach | C17: =17.9*'P&L'!G16-Assumptions!C47 -> 13513.158 | D17: =C17/Assumptions!C48*100 -> 332018.62 | E17: ← Equity Value (₹ Cr) | → Implied Price/share
B18: P/E Approach | C18: =Assumptions!C50*'P&L'!G26 -> 13913.991 | D18: =C18/Assumptions!C48*100 -> 341867.1 | E18: ← Market Cap (₹ Cr) | → Implied Price/share
B19: Average Implied Price (₹) | C19: =AVERAGE(D17,D18) -> 336942.86
B20: vs CMP (Upside/Downside) | C20: =(C19-Assumptions!C51)/Assumptions!C51 -> 306.14937

Sheet Ratios
A1: IFB INDUSTRIES — KEY FINANCIAL RATIOS
A2: All ratios are formulas from P&L, Balance Sheet & Assumptions | No hardcoding
B4: Line Item | C4: FY22A | D4: FY23A | E4: FY24A | F4: FY25A | G4: FY26A | H4: FY27E | I4: FY28E | J4: FY29E
B5: PROFITABILITY RATIOS
B6: Gross Margin % | C6: =('P&L'!C6-'P&L'!C11)/'P&L'!C6 -> 0.216 | D6: =('P&L'!D6-'P&L'!D11)/'P&L'!D6 -> 0.24 | E6: =('P&L'!E6-'P&L'!E11)/'P&L'!E6 -> 0.268 | F6: =('P&L'!F6-'P&L'!F11)/'P&L'!F6 -> 0.283 | G6: =('P&L'!G6-'P&L'!G11)/'P&L'!G6 -> 0.28 | H6: =('P&L'!H6-'P&L'!H11)/'P&L'!H6 -> 0.29 | I6: =('P&L'!I6-'P&L'!I11)/'P&L'!I6 -> 0.295 | J6: =('P&L'!J6-'P&L'!J11)/'P&L'!J6 -> 0.3
B7: EBITDA Margin % | C7: ='P&L'!C16/'P&L'!C6 -> 0.07 | D7: ='P&L'!D16/'P&L'!D6 -> 0.104 | E7: ='P&L'!E16/'P&L'!E6 -> 0.127 | F7: ='P&L'!F16/'P&L'!F6 -> 0.144 | G7: ='P&L'!G16/'P&L'!G6 -> 0.14 | H7: ='P&L'!H16/'P&L'!H6 -> 0.15 | I7: ='P&L'!I16/'P&L'!I6 -> 0.158 | J7: ='P&L'!J16/'P&L'!J6 -> 0.167
B8: EBIT Margin % | C8: ='P&L'!C19/'P&L'!C6 -> 0.036157532 | D8: ='P&L'!D19/'P&L'!D6 -> 0.075003899 | E8: ='P&L'!E19/'P&L'!E6 -> 0.098706865 | F8: ='P&L'!F19/'P&L'!F6 -> 0.11789721 | G8: ='P&L'!G19/'P&L'!G6 -> 0.11740217 | H8: ='P&L'!H19/'P&L'!H6 -> 0.12785796 | I8: ='P&L'!I19/'P&L'!I6 -> 0.13603807 | J8: ='P&L'!J19/'P&L'!J6 -> 0.14543137
B9: PBT Margin % | C9: ='P&L'!C23/'P&L'!C6 -> 0.034360587 | D9: ='P&L'!D23/'P&L'!D6 -> 0.073298246 | E9: ='P&L'!E23/'P&L'!E6 -> 0.099170686 | F9: ='P&L'!F23/'P&L'!F6 -> 0.11951599 | G9: ='P&L'!G23/'P&L'!G6 -> 0.11593239 | H9: ='P&L'!H23/'P&L'!H6 -> 0.12917008 | I9: ='P&L'!I23/'P&L'!I6 -> 0.13823426 | J9: ='P&L'!J23/'P&L'!J6 -> 0.14830719
B10: PAT (Net) Margin % | C10: ='P&L'!C26/'P&L'!C6 -> 0.045699581 | D10: ='P&L'!D26/'P&L'!D6 -> 0.036649123 | E10: ='P&L'!E26/'P&L'!E6 -> 0.075369722 | F10: ='P&L'!F26/'P&L'!F6 -> 0.089636989 | G10: ='P&L'!G26/'P&L'!G6 -> 0.086949293 | H10: ='P&L'!H26/'P&L'!H6 -> 0.095585862 | I10: ='P&L'!I26/'P&L'!I6 -> 0.10229335 | J10: ='P&L'!J26/'P&L'!J6 -> 0.10974732
B11: Return on Equity (ROE %) | C11: ='P&L'!C26/BalanceSheet!C8 -> 0.23954615 | D11: ='P&L'!D26/BalanceSheet!D8 -> 0.22928049 | E11: ='P&L'!E26/BalanceSheet!E8 -> 0.44765047 | F11: ='P&L'!F26/BalanceSheet!F8 -> 0.5163007 | G11: ='P&L'!G26/BalanceSheet!G8 -> 0.50670771 | H11: ='P&L'!H26/BalanceSheet!H8 -> 0.52267892 | I11: ='P&L'!I26/BalanceSheet!I8 -> 0.51906657 | J11: ='P&L'!J26/BalanceSheet!J8 -> 0.51130755
B12: Return on Capital Employed (ROCE %) | C12: ='P&L'!C19/(BalanceSheet!C8+BalanceSheet!C9) -> 0.14633939 | D12: ='P&L'!D19/(BalanceSheet!D8+BalanceSheet!D9) -> 0.37356311 | E12: ='P&L'!E19/(BalanceSheet!E8+BalanceSheet!E9) -> 0.54848454 | F12: ='P&L'!F19/(BalanceSheet!F8+BalanceSheet!F9) -> 0.5897247 | G12: ='P&L'!G19/(BalanceSheet!G8+BalanceSheet!G9) -> 0.63019724 | H12: ='P&L'!H19/(BalanceSheet!H8+BalanceSheet!H9) -> 0.6578481 | I12: ='P&L'!I19/(BalanceSheet!I8+BalanceSheet!I9) -> 0.66083926 | J12: ='P&L'!J19/(BalanceSheet!J8+BalanceSheet!J9) -> 0.65753546
B14: LIQUIDITY & LEVERAGE RATIOS
B15: Current Ratio (x) | C15: =BalanceSheet!C28/BalanceSheet!C15 -> 1.1224467 | D15: =BalanceSheet!D28/BalanceSheet!D15 -> 1.144993 | E15: =BalanceSheet!E28/BalanceSheet!E15 -> 1.0096272 | F15: =BalanceSheet!F28/BalanceSheet!F15 -> 1.0468108 | G15: =BalanceSheet!G28/BalanceSheet!G15 -> 1.0007945 | H15: =BalanceSheet!H28/BalanceSheet!H15 -> 0.97260222 | I15: =BalanceSheet!I28/BalanceSheet!I15 -> 0.96935735 | J15: =BalanceSheet!J28/BalanceSheet!J15 -> 1.0039211
B16: Debt-to-Equity (D/E) | C16: =(BalanceSheet!C9+BalanceSheet!C12)/BalanceSheet!C8 -> 0.56043956 | D16: =(BalanceSheet!D9+BalanceSheet!D12)/BalanceSheet!D8 -> 0.5304878 | E16: =(BalanceSheet!E9+BalanceSheet!E12)/BalanceSheet!E8 -> 0.2231405 | F16: =(BalanceSheet!F9+BalanceSheet!F12)/BalanceSheet!F8 -> 0.29020979 | G16: =(BalanceSheet!G9+BalanceSheet!G12)/BalanceSheet!G8 -> 0.17558887 | H16: =(BalanceSheet!H9+BalanceSheet!H12)/BalanceSheet!H8 -> 0.14349776 | I16: =(BalanceSheet!I9+BalanceSheet!I12)/BalanceSheet!I8 -> 0.10401189 | J16: =(BalanceSheet!J9+BalanceSheet!J12)/BalanceSheet!J8 -> 0.073081608
B17: Interest Coverage (EBIT / Interest) | C17: =IF(Assumptions!C20>0,'P&L'!C19/Assumptions!C20,0) -> 3.5508824 | D17: =IF(Assumptions!D20>0,'P&L'!D19/Assumptions!D20,0) -> 9.3277576 | E17: =IF(Assumptions!E20>0,'P&L'!E19/Assumptions!E20,0) -> 14.187467 | F17: =IF(Assumptions!F20>0,'P&L'!F19/Assumptions!F20,0) -> 21.579556 | G17: =IF(Assumptions!G20>0,'P&L'!G19/Assumptions!G20,0) -> 26.625833 | H17: =IF(Assumptions!H20>0,'P&L'!H19/Assumptions!H20,0) -> 32.48125 | I17: =IF(Assumptions!I20>0,'P&L'!I19/Assumptions!I20,0) -> 44.244762 | J17: =IF(Assumptions!J20>0,'P&L'!J19/Assumptions!J20,0) -> 61.808333
B19: WORKING CAPITAL RATIOS
B20: Debtor Days | C20: =Assumptions!C27 -> 32 | D20: =Assumptions!D27 -> 35 | E20: =Assumptions!E27 -> 37 | F20: =Assumptions!F27 -> 30 | G20: =Assumptions!G27 -> 30 | H20: =Assumptions!H27 -> 30 | I20: =Assumptions!I27 -> 29 | J20: =Assumptions!J27 -> 29
B21: Inventory Days | C21: =Assumptions!C28 -> 104 | D21: =Assumptions!D28 -> 83 | E21: =Assumptions!E28 -> 77 | F21: =Assumptions!F28 -> 81 | G21: =Assumptions!G28 -> 80 | H21: =Assumptions!H28 -> 79 | I21: =Assumptions!I28 -> 78 | J21: =Assumptions!J28 -> 77
B22: Payable Days | C22: =Assumptions!C29 -> 145 | D22: =Assumptions!D29 -> 119 | E22: =Assumptions!E29 -> 137 | F22: =Assumptions!F29 -> 113 | G22: =Assumptions!G29 -> 115 | H22: =Assumptions!H29 -> 115 | I22: =Assumptions!I29 -> 115 | J22: =Assumptions!J29 -> 115
B23: Cash Conversion Cycle (days) | C23: =Assumptions!C27+Assumptions!C28-Assumptions!C29 -> -9 | D23: =Assumptions!D27+Assumptions!D28-Assumptions!D29 -> -1 | E23: =Assumptions!E27+Assumptions!E28-Assumptions!E29 -> -23 | F23: =Assumptions!F27+Assumptions!F28-Assumptions!F29 -> -2 | G23: =Assumptions!G27+Assumptions!G28-Assumptions!G29 -> -5 | H23: =Assumptions!H27+Assumptions!H28-Assumptions!H29 -> -6 | I23: =Assumptions!I27+Assumptions!I28-Assumptions!I29 -> -8 | J23: =Assumptions!J27+Assumptions!J28-Assumptions!J29 -> -9
B25: VALUATION RATIOS (vs CMP in Assumptions)
B26: EPS (₹ per share) | C26: ='P&L'!C29 -> 37.491622 | D26: ='P&L'!D29 -> 36.955283 | E26: ='P&L'!E29 -> 79.851165 | F26: ='P&L'!F29 -> 108.84177 | G26: ='P&L'!G29 -> 116.28133 | H26: ='P&L'!H29 -> 143.19091 | I26: ='P&L'!I29 -> 171.66182 | J26: ='P&L'!J29 -> 206.28182
B27: P/E Ratio (x) [CMP / EPS] | C27: =IF('P&L'!C29>0,Assumptions!C51/'P&L'!C29,0) -> 29.259871 | D27: =IF('P&L'!D29>0,Assumptions!C51/'P&L'!D29,0) -> 29.684525 | E27: =IF('P&L'!E29>0,Assumptions!C51/'P&L'!E29,0) -> 13.738059 | F27: =IF('P&L'!F29>0,Assumptions!C51/'P&L'!F29,0) -> 10.078851 | G27: =IF('P&L'!G29>0,Assumptions!C51/'P&L'!G29,0) -> 9.4340169 | H27: =IF('P&L'!H29>0,Assumptions!C51/'P&L'!H29,0) -> 7.6611009 | I27: =IF('P&L'!I29>0,Assumptions!C51/'P&L'!I29,0) -> 6.3904718 | J27: =IF('P&L'!J29>0,Assumptions!C51/'P&L'!J29,0) -> 5.3179675
B28: P/B Ratio (x) [Mkt Cap / Book Equity] | C28: =(Assumptions!C51*Assumptions!C48)*100/BalanceSheet!C8/100 -> 7.0090895 | D28: =(Assumptions!C51*Assumptions!C48)*100/BalanceSheet!D8/100 -> 6.8060823 | E28: =(Assumptions!C51*Assumptions!C48)*100/BalanceSheet!E8/100 -> 6.1498485 | F28: =(Assumptions!C51*Assumptions!C48)*100/BalanceSheet!F8/100 -> 5.2037179 | G28: =(Assumptions!C51*Assumptions!C48)*100/BalanceSheet!G8/100 -> 4.7802891 | H28: =(Assumptions!C51*Assumptions!C48)*100/BalanceSheet!H8/100 -> 4.004296 | I28: =(Assumptions!C51*Assumptions!C48)*100/BalanceSheet!I8/100 -> 3.3170802 | J28: =(Assumptions!C51*Assumptions!C48)*100/BalanceSheet!J8/100 -> 2.7191169
B29: EV/EBITDA (x) | C29: =IF('P&L'!C16>0,((Assumptions!C51*Assumptions!C48)+Assumptions!C47)*100/'P&L'!C16/100,0) -> 19.645702 | D29: =IF('P&L'!D16>0,((Assumptions!C51*Assumptions!C48)+Assumptions!C47)*100/'P&L'!D16/100,0) -> 10.758242 | E29: =IF('P&L'!E16>0,((Assumptions!C51*Assumptions!C48)+Assumptions!C47)*100/'P&L'!E16/100,0) -> 8.384932 | F29: =IF('P&L'!F16>0,((Assumptions!C51*Assumptions!C48)+Assumptions!C47)*100/'P&L'!F16/100,0) -> 6.4523332 | G29: =IF('P&L'!G16>0,((Assumptions!C51*Assumptions!C48)+Assumptions!C47)*100/'P&L'!G16/100,0) -> 6.025813 | H29: =IF('P&L'!H16>0,((Assumptions!C51*Assumptions!C48)+Assumptions!C47)*100/'P&L'!H16/100,0) -> 5.020819 | I29: =IF('P&L'!I16>0,((Assumptions!C51*Assumptions!C48)+Assumptions!C47)*100/'P&L'!I16/100,0) -> 4.2550457 | J29: =IF('P&L'!J16>0,((Assumptions!C51*Assumptions!C48)+Assumptions!C47)*100/'P&L'!J16/100,0) -> 3.5942155

Sheet Segments
A1: IFB INDUSTRIES — SEGMENT ANALYSIS
A2: Home Appliances vs Engineering | Revenue from Assumptions, margins computed
B4: Line Item | C4: FY22A | D4: FY23A | E4: FY24A | F4: FY25A | G4: FY26A | H4: FY27E | I4: FY28E | J4: FY29E
B5: HOME APPLIANCES SEGMENT
B6: Revenue (₹ Cr) | C6: =Assumptions!C7 -> 2720 | D6: =Assumptions!D7 -> 3416 | E6: =Assumptions!E7 -> 3609 | F6: =Assumptions!F7 -> 4086 | G6: =Assumptions!G7 -> 4362 | H6: =Assumptions!H7 -> 4900 | I6: =Assumptions!I7 -> 5500 | J6: =Assumptions!J7 -> 6160
B7: YoY Growth % | C7: - | D7: =(Assumptions!D7-Assumptions!C7)/Assumptions!C7 -> 0.25588235 | E7: =(Assumptions!E7-Assumptions!D7)/Assumptions!D7 -> 0.056498829 | F7: =(Assumptions!F7-Assumptions!E7)/Assumptions!E7 -> 0.13216958 | G7: =(Assumptions!G7-Assumptions!F7)/Assumptions!F7 -> 0.067547724 | H7: =(Assumptions!H7-Assumptions!G7)/Assumptions!G7 -> 0.12333792 | I7: =(Assumptions!I7-Assumptions!H7)/Assumptions!H7 -> 0.12244898 | J7: =(Assumptions!J7-Assumptions!I7)/Assumptions!I7 -> 0.12
B8: % of Total Revenue | C8: =Assumptions!C7/'P&L'!C6 -> 0.81461515 | D8: =Assumptions!D7/'P&L'!D6 -> 0.83235867 | E8: =Assumptions!E7/'P&L'!E6 -> 0.8369666 | F8: =Assumptions!F7/'P&L'!F6 -> 0.82679077 | G8: =Assumptions!G7/'P&L'!G6 -> 0.80139629 | H8: =Assumptions!H7/'P&L'!H6 -> 0.80367394 | I8: =Assumptions!I7/'P&L'!I6 -> 0.80527086 | J8: =Assumptions!J7/'P&L'!J6 -> 0.80522876
B9: Segment EBIT (₹ Cr) [est.] | C9: ='P&L'!C19*0.8 -> 96.584 | D9: ='P&L'!D19*0.8 -> 246.2528 | E9: ='P&L'!E19*0.8 -> 340.4992 | F9: ='P&L'!F19*0.8 -> 466.1184 | G9: ='P&L'!G19*0.8 -> 511.216 | H9: ='P&L'!H19*0.8 -> 623.64 | I9: ='P&L'!I19*0.8 -> 743.312 | J9: ='P&L'!J19*0.8 -> 890.04
B10: EBIT Margin % | C10: =Segments!C9/Assumptions!C7 -> 0.035508824 | D10: =Segments!D9/Assumptions!D7 -> 0.072088056 | E10: =Segments!E9/Assumptions!E7 -> 0.094347243 | F10: =Segments!F9/Assumptions!F7 -> 0.11407695 | G10: =Segments!G9/Assumptions!G7 -> 0.11719762 | H10: =Segments!H9/Assumptions!H7 -> 0.12727347 | I10: =Segments!I9/Assumptions!I7 -> 0.13514764 | J10: =Segments!J9/Assumptions!J7 -> 0.14448701
B11: HOME APPLIANCES PRODUCT MIX (% of HA Revenue)
B12: Washing Machines | C12: =Assumptions!C7*0.5 -> 1360 | D12: =Assumptions!D7*0.477 -> 1629.432 | E12: =Assumptions!E7*0.46 -> 1660.14 | F12: =Assumptions!F7*0.44 -> 1797.84 | G12: =Assumptions!G7*0.436 -> 1901.832 | H12: =Assumptions!H7*0.43 -> 2107 | I12: =Assumptions!I7*0.42 -> 2310 | J12: =Assumptions!J7*0.41 -> 2525.6
B13: Air Conditioners | C13: =Assumptions!C7*0.235 -> 639.2 | D13: =Assumptions!D7*0.24 -> 819.84 | E13: =Assumptions!E7*0.249 -> 898.641 | F13: =Assumptions!F7*0.247 -> 1009.242 | G13: =Assumptions!G7*0.252 -> 1099.224 | H13: =Assumptions!H7*0.255 -> 1249.5 | I13: =Assumptions!I7*0.26 -> 1430 | J13: =Assumptions!J7*0.263 -> 1620.08
B14: Microwave Ovens | C14: =Assumptions!C7*0.092 -> 250.24 | D14: =Assumptions!D7*0.091 -> 310.856 | E14: =Assumptions!E7*0.083 -> 299.547 | F14: =Assumptions!F7*0.078 -> 318.708 | G14: =Assumptions!G7*0.076 -> 331.512 | H14: =Assumptions!H7*0.076 -> 372.4 | I14: =Assumptions!I7*0.075 -> 412.5 | J14: =Assumptions!J7*0.074 -> 455.84
B15: Dishwashers & Others | C15: =Assumptions!C7*0.074 -> 201.28 | D15: =Assumptions!D7*0.079 -> 269.864 | E15: =Assumptions!E7*0.089 -> 321.201 | F15: =Assumptions!F7*0.093 -> 379.998 | G15: =Assumptions!G7*0.096 -> 418.752 | H15: =Assumptions!H7*0.1 -> 490 | I15: =Assumptions!I7*0.105 -> 577.5 | J15: =Assumptions!J7*0.11 -> 677.6
B16: After-Sales Service | C16: =Assumptions!C7*0.099 -> 269.28 | D16: =Assumptions!D7*0.113 -> 386.008 | E16: =Assumptions!E7*0.119 -> 429.471 | F16: =Assumptions!F7*0.141 -> 576.126 | G16: =Assumptions!G7*0.14 -> 610.68 | H16: =Assumptions!H7*0.139 -> 681.1 | I16: =Assumptions!I7*0.14 -> 770 | J16: =Assumptions!J7*0.143 -> 880.88
B18: ENGINEERING SEGMENT (Fine Blanked Components)
B19: Revenue (₹ Cr) | C19: =Assumptions!C8 -> 619 | D19: =Assumptions!D8 -> 688 | E19: =Assumptions!E8 -> 703 | F19: =Assumptions!F8 -> 856 | G19: =Assumptions!G8 -> 880 | H19: =Assumptions!H8 -> 990 | I19: =Assumptions!I8 -> 1109 | J19: =Assumptions!J8 -> 1242
B20: YoY Growth % | C20: - | D20: =(Assumptions!D8-Assumptions!C8)/Assumptions!C8 -> 0.11147011 | E20: =(Assumptions!E8-Assumptions!D8)/Assumptions!D8 -> 0.021802326 | F20: =(Assumptions!F8-Assumptions!E8)/Assumptions!E8 -> 0.21763869 | G20: =(Assumptions!G8-Assumptions!F8)/Assumptions!F8 -> 0.028037383 | H20: =(Assumptions!H8-Assumptions!G8)/Assumptions!G8 -> 0.125 | I20: =(Assumptions!I8-Assumptions!H8)/Assumptions!H8 -> 0.12020202 | J20: =(Assumptions!J8-Assumptions!I8)/Assumptions!I8 -> 0.11992786
B21: % of Total Revenue | C21: =Assumptions!C8/'P&L'!C6 -> 0.18538485 | D21: =Assumptions!D8/'P&L'!D6 -> 0.16764133 | E21: =Assumptions!E8/'P&L'!E6 -> 0.1630334 | F21: =Assumptions!F8/'P&L'!F6 -> 0.17320923 | G21: =Assumptions!G8/'P&L'!G6 -> 0.16167555 | H21: =Assumptions!H8/'P&L'!H6 -> 0.16237494 | I21: =Assumptions!I8/'P&L'!I6 -> 0.16237189 | J21: =Assumptions!J8/'P&L'!J6 -> 0.16235294
B22: Segment EBIT (₹ Cr) [est.] | C22: ='P&L'!C19*0.2 -> 24.146 | D22: ='P&L'!D19*0.2 -> 61.5632 | E22: ='P&L'!E19*0.2 -> 85.1248 | F22: ='P&L'!F19*0.2 -> 116.5296 | G22: ='P&L'!G19*0.2 -> 127.804 | H22: ='P&L'!H19*0.2 -> 155.91 | I22: ='P&L'!I19*0.2 -> 185.828 | J22: ='P&L'!J19*0.2 -> 222.51
B23: EBIT Margin % | C23: =Segments!C22/Assumptions!C8 -> 0.039008078 | D23: =Segments!D22/Assumptions!D8 -> 0.089481395 | E23: =Segments!E22/Assumptions!E8 -> 0.12108791 | F23: =Segments!F22/Assumptions!F8 -> 0.13613271 | G23: =Segments!G22/Assumptions!G8 -> 0.14523182 | H23: =Segments!H22/Assumptions!H8 -> 0.15748485 | I23: =Segments!I22/Assumptions!I8 -> 0.16756357 | J23: =Segments!J22/Assumptions!J8 -> 0.17915459
B25: CONSOLIDATED SUMMARY
B26: Total Revenue (₹ Cr) | C26: ='P&L'!C6 -> 3339 | D26: ='P&L'!D6 -> 4104 | E26: ='P&L'!E6 -> 4312 | F26: ='P&L'!F6 -> 4942 | G26: ='P&L'!G6 -> 5443 | H26: ='P&L'!H6 -> 6097 | I26: ='P&L'!I6 -> 6830 | J26: ='P&L'!J6 -> 7650
B27: Total EBIT (₹ Cr) | C27: ='P&L'!C19 -> 120.73 | D27: ='P&L'!D19 -> 307.816 | E27: ='P&L'!E19 -> 425.624 | F27: ='P&L'!F19 -> 582.648 | G27: ='P&L'!G19 -> 639.02 | H27: ='P&L'!H19 -> 779.55 | I27: ='P&L'!I19 -> 929.14 | J27: ='P&L'!J19 -> 1112.55
B28: Blended EBIT Margin % | C28: ='P&L'!C19/'P&L'!C6 -> 0.036157532 | D28: ='P&L'!D19/'P&L'!D6 -> 0.075003899 | E28: ='P&L'!E19/'P&L'!E6 -> 0.098706865 | F28: ='P&L'!F19/'P&L'!F6 -> 0.11789721 | G28: ='P&L'!G19/'P&L'!G6 -> 0.11740217 | H28: ='P&L'!H19/'P&L'!H6 -> 0.12785796 | I28: ='P&L'!I19/'P&L'!I6 -> 0.13603807 | J28: ='P&L'!J19/'P&L'!J6 -> 0.14543137
